Workbook

Sheet Introduction
D2: Introduction & Information
A5: All previous financial data were taked from Annual Reports - All publicly available
A7: Purpose of creating this model is purely for personal development & practice & curiosity
A9: MODEL AND FINANCIAL DATA DO NOT CONTAIN ANY SENSITIVE DATA & FINANCIAL ADVICE
A11: Please do not publish the model anywhere. But if you are interested in using or developing the model for your personal development & curiosity, feel free
A13: If you`d like to discuss the model or have any questions about calculations & formulas, please contact me
A15: Enjoy Exploring!
A17: Best Regards,
A18: Berk Tansuker
A20: Github
A21: LinkedIn
A22: E-Mail

Sheet 01_Raw_Data_BMW
A2: Item | B2: 2025 | C2: 2024 | D2: 2023 | E2: 2022 | F2: 2021 | G2: 2020
A3: Revenues | B3: 98805 | C3: 105317 | D3: 107874 | E3: 98807 | F3: 88526 | G3: 75040
A4: Cost of sales | B4: -83907 | C4: -88214 | D4: -90865 | E4: -81653 | F4: -72283 | G4: -63726
A5: Gross profit | B5: 14898 | C5: 17103 | D5: 17009 | E5: 17154 | F5: 16243 | G5: 11314
A6: Selling expenses | B6: -4119 | C6: -4261 | D6: -4123 | E6: -4058 | F6: -3858 | G6: -4030
A7: Administrative expenses | B7: -3864 | C7: -4068 | D7: -3824 | E7: -3624 | F7: -3243 | G7: -2747
A8: Research and development expenses | B8: -7775 | C8: -8315 | D8: -6924 | E8: -6782 | F8: -6451 | G8: -5394
A9: Other operating income | B9: 2849 | C9: 2062 | D9: 1872 | E9: 2529 | F9: 2199 | G9: 1237
A10: Other operating expense | B10: -2262 | C10: -1953 | D10: -2067 | E10: -2889 | F10: -1460 | G10: -1250
A11: Result on investments | B11: 5503 | C11: 3917 | D11: 3592 | E11: 8520 | F11: 2991 | G11: 3084
A12: Financial result | B12: -1001 | C12: -378 | D12: -84 | E12: -2926 | F12: -426 | G12: -280
A13: Income taxes | B13: -285 | C13: -566 | D13: -1067 | E13: -1594 | F13: -1068 | G13: -214
... A48: Total equity and liabilities | B48: 69728 | C48: 66570 | D48: 67824 | E48: 72243 | F48: 64705 | G48: 57640
A53: Average Assets | B53: =(B32+C32)/2 -> 68149 | C53: =(C32+D32)/2 -> 67197 | D53: =(D32+E32)/2 -> 70033.5 | E53: =(E32+F32)/2 -> 68474 | F53: =(F32+G32)/2 -> 61172.5

Sheet 01_Raw_Data_Mercedes
A2: Item | B2: 2025 | C2: 2024 | D2: 2023 | E2: 2022 | F2: 2021 | G2: 2020
A3: Revenue | B3: 132214 | C3: 145594 | D3: 153218 | E3: 150017 | F3: 133893 | G3: 121778
A4: Cost of sales | B4: -109881 | C4: -117018 | D4: -118839 | E4: -115997 | F4: -103218 | G4: -101592
A5: Gross profit | B5: 22333 | C5: 28576 | D5: 34379 | E5: 34020 | F5: 30675 | G5: 20186
A6: Selling expenses | B6: -9718 | C6: -9993 | D6: -9728 | E6: -9482 | F6: -9194 | G6: -8966
A7: General administrative expenses | B7: -2477 | C7: -2529 | D7: -2688 | E7: -2584 | F7: -2808 | G7: -2507
A8: Research and development costs | B8: -6055 | C8: -5580 | D8: -6230 | E8: -5602 | F8: -5467 | G8: -4839
A9: Other operating income | B9: 1551 | C9: 2507 | D9: 2206 | E9: 3323 | F9: 2888 | G9: 2384
A10: Other operating expense | B10: -1025 | C10: -483 | D10: -516 | E10: -1289 | F10: -1735 | G10: -591
A11: Equity-method gains/losses | B11: 1118 | C11: 1138 | D11: 2129 | E11: 1732 | F11: 1352 | G11: 747
A12: Other financial income/expense | B12: 93 | C12: -37 | D12: 108 | E12: 340 | F12: 317 | G12: -323
A13: Interest income | B13: 623 | C13: 738 | D13: 678 | E13: 273 | F13: 212 | G13: 224
... A72: TOTAL EQUITY AND LIABILITIES | B72: 255466 | C72: 265010 | D72: 263022 | E72: 260015 | F72: 259831 | G72: 285737
A75: Model Helper
A76: Provisions | B76: =B51+B52+B62 -> 16265 | C76: =C51+C52+C62 -> 15972 | D76: =D51+D52+D62 -> 16390 | E76: =E51+E52+E62 -> 17044 | F76: =F51+F52+F62 -> 21321 | G76: =G51+G52+G62 -> 32520
A77: Financial Debt / Financing Liabilities | B77: =B53+B63 -> 100006 | C77: =C53+C63 -> 112798 | D77: =D53+D63 -> 108638 | E77: =E53+E63 -> 111837 | F77: =F53+F63 -> 125843 | G77: =G53+G63 -> 145842
A78: Other Liabilities | B78: =B54+B55+B56+B57+B58+B59+B64+B65+B66+B67+B68+B69 -> 34290 | C78: =C54+C55+C56+C57+C58+C59+C64+C65+C66+C67+C68+C69 -> 31298 | D78: =D54+D55+D56+D57+D58+D59+D64+D65+D66+D67+D68+D69 -> 32350 | E78: =E54+E55+E56+E57+E58+E59+E64+E65+E66+E67+E68+E69 -> 32390 | F78: =F54+F55+F56+F57+F58+F59+F64+F65+F66+F67+F68+F69 -> 28845 | G78: =G54+G55+G56+G57+G58+G59+G64+G65+G66+G67+G68+G69 -> 32749
A80: Property, Plant & Equipment / Lease Assets | B80: =B22+B23 -> 66812 | C80: =C22+C23 -> 71757 | D80: =D22+D23 -> 67802 | E80: =E22+E23 -> 68802 | F80: =F22+F23 -> 72330 | G80: =G22+G23 -> 82798
A82: Investments | B82: =B24+B25+B26 -> 52565 | C82: =C24+C25+C26 -> 61977 | D82: =D24+D25+D26 -> 63545 | E82: =E24+E25+E26 -> 62590 | F82: =F24+F25+F26 -> 61416 | G82: =G24+G25+G26 -> 59939
A83: Other Non-Current Assets | B83: =B27+B28+B29+B30 -> 13410 | C83: =C27+C28+C29+C30 -> 10073 | D83: =D27+D28+D29+D30 -> 10050 | E83: =E27+E28+E29+E30 -> 9880 | F83: =F27+F28+F29+F30 -> 8151 | G83: =G27+G28+G29+G30 -> 11337
A84: Other Current Assets | B84: =B36+B37+B38+B39+B40 -> 25707 | C84: =C36+C37+C38+C39+C40 -> 14729 | D84: =D36+D37+D38+D39+D40 -> 15026 | E84: =E36+E37+E38+E39+E40 -> 14162 | F84: =F36+F37+F38+F39+F40 -> 17000 | G84: =G36+G37+G38+G39+G40 -> 12647
A85: Average Assets | B85: =(B42+C42)/2 -> 260238 | C85: =(C42+D42)/2 -> 264016 | D85: =(D42+E42)/2 -> 261518.5 | E85: =(E42+F42)/2 -> 259923 | F85: =(F42+G42)/2 -> 272784

Sheet 01_Raw_Data_Volkswagen
A2: Item | B2: 2025 | C2: 2024 | D2: 2023 | E2: 2022 | F2: 2021 | G2: 2020
A3: Sales revenue | B3: 321913 | C3: 324656 | D3: 322284 | E3: 279050 | F3: 250200 | G3: 222884
A4: Cost of sales | B4: -270671 | C4: -265184 | D4: -261262 | E4: -226866 | F4: -202959 | G4: -183937
A5: Gross result | B5: 51243 | C5: 59472 | D5: 61022 | E5: 52184 | F5: 47241 | G5: 38947
A6: Distribution expenses | B6: -22804 | C6: -22320 | D6: -21340 | E6: -19840 | F6: -19228 | G6: -18407
A7: Administrative expenses | B7: -12541 | C7: -12754 | D7: -12724 | E7: -11655 | F7: -10420 | G7: -9399
A8: Other operating income | B8: 13615 | C8: 14974 | D8: 15152 | E8: 19234 | F8: 14731 | G8: 12438
A9: Other operating expenses | B9: -20644 | C9: -20312 | D9: -19534 | E9: -17813 | F9: -13049 | G9: -13904
A10: Operating result | B10: 8868 | C10: 19060 | D10: 22576 | E10: 22109 | F10: 19275 | G10: 9675
A11: Share of equity investments | B11: 930 | C11: 375 | D11: 2291 | E11: 2403 | F11: 2321 | G11: 2756
A12: Interest income | B12: 1824 | C12: 2419 | D12: 2658 | E12: 1325 | F12: 810 | G12: 793
A13: Interest expenses | B13: -3245 | C13: -3446 | D13: -3592 | E13: -408 | F13: -1818 | G13: -2291
... A72: TOTAL EQUITY AND LIABILITIES | B72: 644467 | C72: 632905 | D72: 600338 | E72: 564013 | F72: 528609 | G72: 497114
A76: Model Helper
A77: Provisions | B77: =B58+B59+B60+B67+B68 -> 79848 | C77: =C58+C59+C60+C67+C68 -> 84448 | D77: =D58+D59+D60+D67+D68 -> 81139 | E77: =E58+E59+E60+E67+E68 -> 80338 | F77: =F58+F59+F60+F67+F68 -> 96857 | G77: =G58+G59+G60+G67+G68 -> 96238
A78: Financial Debt / Financing Liabilities | B78: =B54+B62 -> 264703 | C78: =C54+C62 -> 254081 | D78: =D54+D62 -> 232799 | E78: =E54+E62 -> 205185 | F78: =F54+F62 -> 210202 | G78: =G54+G62 -> 203457
A79: Other Liabilities | B79: =B55+B56+B57+B64+B65+B66+B69 -> 66372 | C79: =C55+C56+C57+C64+C65+C66+C69 -> 67872 | D79: =D55+D56+D57+D64+D65+D66+D69 -> 65588 | E79: =E55+E56+E57+E64+E65+E66+E69 -> 71424 | F79: =F55+F56+F57+F64+F65+F66+F69 -> 51771 | G79: =G55+G56+G57+G64+G65+G66+G69 -> 45961
A81: Property, Plant & Equipment / Lease Assets | B81: =B24+B25 -> 155562 | C81: =C24+C25 -> 144645 | D81: =D24+D25 -> 130974 | E81: =E24+E25 -> 123270 | F81: =F24+F25 -> 123394 | G81: =G24+G25 -> 114570
A83: Investments | B83: =B26+B27+B28+B29 -> 119201 | C83: =C26+C27+C28+C29 -> 117709 | D83: =D26+D27+D28+D29 -> 111776 | E83: =E26+E27+E28+E29 -> 103711 | F83: =F26+F27+F28+F29 -> 101100 | G83: =G26+G27+G28+G29 -> 95068
A84: Other Non-Current Assets | B84: =B30+B31+B32+B33 -> 30365 | C84: =C30+C31+C32+C33 -> 31987 | D84: =D30+D31+D32+D33 -> 28836 | E84: =E30+E31+E32+E33 -> 29632 | F84: =F30+F31+F32+F33 -> 26079 | G84: =G30+G31+G32+G33 -> 24563
A85: Other Current Assets | B85: =B38+B39+B40+B41+B43 -> 62235 | C85: =C38+C39+C40+C41+C43 -> 58230 | D85: =D38+D39+D40+D41+D43 -> 54363 | E85: =E38+E39+E40+E41+E43 -> 62632 | F85: =F38+F39+F40+F41+F43 -> 44881 | G85: =G38+G39+G40+G41+G43 -> 42963
A86: Average Assets | B86: =(B45+C45)/2 -> 638686 | C86: =(C45+D45)/2 -> 616621.5 | D86: =(D45+E45)/2 -> 582175.5 | E86: =(E45+F45)/2 -> 546311 | F86: =(F45+G45)/2 -> 512861.5

Sheet 01_All_Raw_Data
A2: Year | B2: 2025 | E2: 2024 | H2: 2023 | K2: 2022 | N2: 2021 | Q2: 2020
A3: Item | B3: BMW | C3: Mercedes | D3: Volkswagen | E3: BMW | F3: Mercedes | G3: Volkswagen | H3: BMW | I3: Mercedes | J3: Volkswagen | K3: BMW | L3: Mercedes | M3: Volkswagen | N3: BMW | O3: Mercedes | P3: Volkswagen | Q3: BMW | R3: Mercedes | S3: Volkswagen
A4: Revenues | B4: ='01_Raw_Data_BMW'!B3 -> 98805 | C4: ='01_Raw_Data_Mercedes'!B3 -> 132214 | D4: ='01_Raw_Data_Volkswagen'!B3 -> 321913 | E4: ='01_Raw_Data_BMW'!C3 -> 105317 | F4: ='01_Raw_Data_Mercedes'!C3 -> 145594 | G4: ='01_Raw_Data_Volkswagen'!C3 -> 324656 | H4: ='01_Raw_Data_BMW'!D3 -> 107874 | I4: ='01_Raw_Data_Mercedes'!D3 -> 153218 | J4: ='01_Raw_Data_Volkswagen'!D3 -> 322284 | K4: ='01_Raw_Data_BMW'!E3 -> 98807 | L4: ='01_Raw_Data_Mercedes'!E3 -> 150017 | M4: ='01_Raw_Data_Volkswagen'!E3 -> 279050 | N4: ='01_Raw_Data_BMW'!F3 -> 88526 | O4: ='01_Raw_Data_Mercedes'!F3 -> 133893 | P4: ='01_Raw_Data_Volkswagen'!F3 -> 250200 | Q4: ='01_Raw_Data_BMW'!G3 -> 75040 | R4: ='01_Raw_Data_Mercedes'!G3 -> 121778 | S4: ='01_Raw_Data_Volkswagen'!G3 -> 222884
A5: Cost of Sales | B5: ='01_Raw_Data_BMW'!B4 -> -83907 | C5: ='01_Raw_Data_Mercedes'!B4 -> -109881 | D5: ='01_Raw_Data_Volkswagen'!B4 -> -270671 | E5: ='01_Raw_Data_BMW'!C4 -> -88214 | F5: ='01_Raw_Data_Mercedes'!C4 -> -117018 | G5: ='01_Raw_Data_Volkswagen'!C4 -> -265184 | H5: ='01_Raw_Data_BMW'!D4 -> -90865 | I5: ='01_Raw_Data_Mercedes'!D4 -> -118839 | J5: ='01_Raw_Data_Volkswagen'!D4 -> -261262 | K5: ='01_Raw_Data_BMW'!E4 -> -81653 | L5: ='01_Raw_Data_Mercedes'!E4 -> -115997 | M5: ='01_Raw_Data_Volkswagen'!E4 -> -226866 | N5: ='01_Raw_Data_BMW'!F4 -> -72283 | O5: ='01_Raw_Data_Mercedes'!F4 -> -103218 | P5: ='01_Raw_Data_Volkswagen'!F4 -> -202959 | Q5: ='01_Raw_Data_BMW'!G4 -> -63726 | R5: ='01_Raw_Data_Mercedes'!G4 -> -101592 | S5: ='01_Raw_Data_Volkswagen'!G4 -> -183937
A6: Gross Profit | B6: ='01_Raw_Data_BMW'!B5 -> 14898 | C6: ='01_Raw_Data_Mercedes'!B5 -> 22333 | D6: ='01_Raw_Data_Volkswagen'!B5 -> 51243 | E6: ='01_Raw_Data_BMW'!C5 -> 17103 | F6: ='01_Raw_Data_Mercedes'!C5 -> 28576 | G6: ='01_Raw_Data_Volkswagen'!C5 -> 59472 | H6: ='01_Raw_Data_BMW'!D5 -> 17009 | I6: ='01_Raw_Data_Mercedes'!D5 -> 34379 | J6: ='01_Raw_Data_Volkswagen'!D5 -> 61022 | K6: ='01_Raw_Data_BMW'!E5 -> 17154 | L6: ='01_Raw_Data_Mercedes'!E5 -> 34020 | M6: ='01_Raw_Data_Volkswagen'!E5 -> 52184 | N6: ='01_Raw_Data_BMW'!F5 -> 16243 | O6: ='01_Raw_Data_Mercedes'!F5 -> 30675 | P6: ='01_Raw_Data_Volkswagen'!F5 -> 47241 | Q6: ='01_Raw_Data_BMW'!G5 -> 11314 | R6: ='01_Raw_Data_Mercedes'!G5 -> 20186 | S6: ='01_Raw_Data_Volkswagen'!G5 -> 38947
A7: Total Operating Expenses | B7: =SUM('01_Raw_Data_BMW'!B6:B10) -> -15171 | C7: =SUM('01_Raw_Data_Mercedes'!B6:B10) -> -17724 | D7: =SUM('01_Raw_Data_Volkswagen'!B6:B9) -> -42374 | E7: =SUM('01_Raw_Data_BMW'!C6:C10) -> -16535 | F7: =SUM('01_Raw_Data_Mercedes'!C6:C10) -> -16078 | G7: =SUM('01_Raw_Data_Volkswagen'!C6:C9) -> -40412 | H7: =SUM('01_Raw_Data_BMW'!D6:D10) -> -15066 | I7: =SUM('01_Raw_Data_Mercedes'!D6:D10) -> -16956 | J7: =SUM('01_Raw_Data_Volkswagen'!D6:D9) -> -38446 | K7: =SUM('01_Raw_Data_BMW'!E6:E10) -> -14824 | L7: =SUM('01_Raw_Data_Mercedes'!E6:E10) -> -15634 | M7: =SUM('01_Raw_Data_Volkswagen'!E6:E9) -> -30074 | N7: =SUM('01_Raw_Data_BMW'!F6:F10) -> -12813 | O7: =SUM('01_Raw_Data_Mercedes'!F6:F10) -> -16316 | P7: =SUM('01_Raw_Data_Volkswagen'!F6:F9) -> -27966 | Q7: =SUM('01_Raw_Data_BMW'!G6:G10) -> -12184 | R7: =SUM('01_Raw_Data_Mercedes'!G6:G10) -> -14519 | S7: =SUM('01_Raw_Data_Volkswagen'!G6:G9) -> -29272
A8: Operating Profit (EBIT) | B8: =SUM(B6:B7) -> -273 | C8: =SUM(C6:C7) -> 4609 | D8: =SUM(D6:D7) -> 8869 | E8: =SUM(E6:E7) -> 568 | F8: =SUM(F6:F7) -> 12498 | G8: =SUM(G6:G7) -> 19060 | H8: =SUM(H6:H7) -> 1943 | I8: =SUM(I6:I7) -> 17423 | ... S8: =SUM(S6:S7) -> 9675
A9: Other Income / Loss | B9: =SUM('01_Raw_Data_BMW'!B11:B12) -> 4502 | C9: =SUM('01_Raw_Data_Mercedes'!B11:B14) -> 1675 | D9: =SUM('01_Raw_Data_Volkswagen'!B11:B14) -> 439 | E9: =SUM('01_Raw_Data_BMW'!C11:C12) -> 3539 | F9: =SUM('01_Raw_Data_Mercedes'!C11:C14) -> 1649 | G9: =SUM('01_Raw_Data_Volkswagen'!C11:C14) -> -2254 | H9: =SUM('01_Raw_Data_BMW'!D11:D12) -> 3508 | I9: =SUM('01_Raw_Data_Mercedes'!D11:D14) -> 2661 | J9: =SUM('01_Raw_Data_Volkswagen'!D11:D14) -> 618 | K9: =SUM('01_Raw_Data_BMW'!E11:E12) -> 5594 | L9: =SUM('01_Raw_Data_Mercedes'!E11:E14) -> 1918 | M9: =SUM('01_Raw_Data_Volkswagen'!E11:E14) -> -39 | N9: =SUM('01_Raw_Data_BMW'!F11:F12) -> 2565 | O9: =SUM('01_Raw_Data_Mercedes'!F11:F14) -> 1452 | P9: =SUM('01_Raw_Data_Volkswagen'!F11:F14) -> 850 | Q9: =SUM('01_Raw_Data_BMW'!G11:G12) -> 2804 | R9: =SUM('01_Raw_Data_Mercedes'!G11:G14) -> 290 | S9: =SUM('01_Raw_Data_Volkswagen'!G11:G14) -> 1991
A10: Profit Before Tax (EBT) | B10: =SUM(B8:B9) -> 4229 | C10: =SUM(C8:C9) -> 6284 | D10: =SUM(D8:D9) -> 9308 | E10: =SUM(E8:E9) -> 4107 | F10: =SUM(F8:F9) -> 14147 | G10: =SUM(G8:G9) -> 16806 | H10: =SUM(H8:H9) -> 5451 | I10: =SUM(I8:I9) -> 20084 | ... S10: =SUM(S8:S9) -> 11666
A11: Income Taxes | B11: ='01_Raw_Data_BMW'!B13 -> -285 | C11: ='01_Raw_Data_Mercedes'!B16 -> -953 | D11: ='01_Raw_Data_Volkswagen'!B17 -> -2403 | E11: ='01_Raw_Data_BMW'!C13 -> -566 | F11: ='01_Raw_Data_Mercedes'!C16 -> -3738 | G11: ='01_Raw_Data_Volkswagen'!C17 -> -4411 | H11: ='01_Raw_Data_BMW'!D13 -> -1067 | I11: ='01_Raw_Data_Mercedes'!D16 -> -5553 | J11: ='01_Raw_Data_Volkswagen'!D17 -> -5266 | K11: ='01_Raw_Data_BMW'!E13 -> -1594 | L11: ='01_Raw_Data_Mercedes'!E16 -> -5495 | M11: ='01_Raw_Data_Volkswagen'!E17 -> -6217 | N11: ='01_Raw_Data_BMW'!F13 -> -1068 | O11: ='01_Raw_Data_Mercedes'!F16 -> -4761 | P11: ='01_Raw_Data_Volkswagen'!F17 -> -4698 | Q11: ='01_Raw_Data_BMW'!G13 -> -214 | R11: ='01_Raw_Data_Mercedes'!G16 -> -1926 | S11: ='01_Raw_Data_Volkswagen'!G17 -> -2843
A12: Other Taxes | B12: ='01_Raw_Data_BMW'!B15 -> -17 | C12: 0 | D12: 0 | E12: ='01_Raw_Data_BMW'!C15 -> -17 | F12: 0 | G12: 0 | H12: ='01_Raw_Data_BMW'!D15 -> -18 | I12: 0 | J12: 0 | K12: ='01_Raw_Data_BMW'!E15 -> -19 | L12: 0 | M12: 0 | N12: ='01_Raw_Data_BMW'!F15 -> -17 | O12: 0 | P12: 0 | Q12: ='01_Raw_Data_BMW'!G15 -> -18 | R12: 0 | S12: 0
A13: Discontinued Operations (After Tax) | B13: 0 | C13: ='01_Raw_Data_Mercedes'!B17 -> 0 | D13: 0 | E13: 0 | F13: ='01_Raw_Data_Mercedes'!C17 -> 0 | G13: 0 | H13: 0 | I13: ='01_Raw_Data_Mercedes'!D17 -> 0 | J13: 0 | K13: 0 | L13: ='01_Raw_Data_Mercedes'!E17 -> 0 | M13: 0 | N13: 0 | O13: ='01_Raw_Data_Mercedes'!F17 -> 12346 | P13: 0 | Q13: 0 | R13: ='01_Raw_Data_Mercedes'!G17 -> -22 | S13: 0
A14: Net profit | B14: =SUM(B10:B13) -> 3927 | C14: =SUM(C10:C13) -> 5331 | D14: =SUM(D10:D13) -> 6905 | E14: =SUM(E10:E13) -> 3524 | F14: =SUM(F10:F13) -> 10409 | G14: =SUM(G10:G13) -> 12395 | H14: =SUM(H10:H13) -> 4366 | I14: =SUM(I10:I13) -> 14531 | ... S14: =SUM(S10:S13) -> 8823
A17: Year | B17: 2025 | E17: 2024 | H17: 2023 | K17: 2022 | N17: 2021 | Q17: 2020
A18: Assets | B18: BMW | C18: Mercedes | D18: Volkswagen | E18: BMW | F18: Mercedes | G18: Volkswagen | H18: BMW | I18: Mercedes | J18: Volkswagen | K18: BMW | L18: Mercedes | M18: Volkswagen | N18: BMW | O18: Mercedes | P18: Volkswagen | Q18: BMW | R18: Mercedes | S18: Volkswagen
A19: Cash & Cash Equivalents | B19: ='01_Raw_Data_BMW'!B28 -> 8407 | C19: ='01_Raw_Data_Mercedes'!B35 -> 12254 | D19: ='01_Raw_Data_Volkswagen'!B42 -> 38801 | E19: ='01_Raw_Data_BMW'!C28 -> 8142 | F19: ='01_Raw_Data_Mercedes'!C35 -> 14511 | G19: ='01_Raw_Data_Volkswagen'!C42 -> 40296 | H19: ='01_Raw_Data_BMW'!D28 -> 6145 | I19: ='01_Raw_Data_Mercedes'!D35 -> 15962 | J19: ='01_Raw_Data_Volkswagen'!D42 -> 43449 | K19: ='01_Raw_Data_BMW'!E28 -> 6207 | L19: ='01_Raw_Data_Mercedes'!E35 -> 17679 | M19: ='01_Raw_Data_Volkswagen'!E42 -> 29172 | N19: ='01_Raw_Data_BMW'!F28 -> 8824 | O19: ='01_Raw_Data_Mercedes'!F35 -> 23120 | P19: ='01_Raw_Data_Volkswagen'!F42 -> 39723 | Q19: ='01_Raw_Data_BMW'!G28 -> 6822 | R19: ='01_Raw_Data_Mercedes'!G35 -> 23048 | S19: ='01_Raw_Data_Volkswagen'!G42 -> 33909
A20: Trade Receivables | B20: ='01_Raw_Data_BMW'!B24 -> 1164 | C20: ='01_Raw_Data_Mercedes'!B33 -> 5851 | D20: ='01_Raw_Data_Volkswagen'!B36 -> 20760 | E20: ='01_Raw_Data_BMW'!C24 -> 1005 | F20: ='01_Raw_Data_Mercedes'!C33 -> 6973 | G20: ='01_Raw_Data_Volkswagen'!C36 -> 21130 | H20: ='01_Raw_Data_BMW'!D24 -> 1349 | I20: ='01_Raw_Data_Mercedes'!D33 -> 7281 | J20: ='01_Raw_Data_Volkswagen'!D36 -> 21849 | K20: ='01_Raw_Data_BMW'!E24 -> 1161 | L20: ='01_Raw_Data_Mercedes'!E33 -> 8100 | M20: ='01_Raw_Data_Volkswagen'!E36 -> 18534 | N20: ='01_Raw_Data_BMW'!F24 -> 758 | O20: ='01_Raw_Data_Mercedes'!F33 -> 7673 | P20: ='01_Raw_Data_Volkswagen'!F36 -> 15521 | Q20: ='01_Raw_Data_BMW'!G24 -> 778 | R20: ='01_Raw_Data_Mercedes'!G33 -> 10649 | S20: ='01_Raw_Data_Volkswagen'!G36 -> 16243
A21: Inventories | B21: ='01_Raw_Data_BMW'!B23 -> 7296 | C21: ='01_Raw_Data_Mercedes'!B32 -> 23933 | D21: ='01_Raw_Data_Volkswagen'!B35 -> 56042 | E21: ='01_Raw_Data_BMW'!C23 -> 7766 | F21: ='01_Raw_Data_Mercedes'!C32 -> 26234 | G21: ='01_Raw_Data_Volkswagen'!C35 -> 56720 | H21: ='01_Raw_Data_BMW'!D23 -> 8505 | I21: ='01_Raw_Data_Mercedes'!D32 -> 27294 | J21: ='01_Raw_Data_Volkswagen'!D35 -> 53601 | K21: ='01_Raw_Data_BMW'!E23 -> 7523 | L21: ='01_Raw_Data_Mercedes'!E32 -> 25621 | M21: ='01_Raw_Data_Volkswagen'!E35 -> 52274 | N21: ='01_Raw_Data_BMW'!F23 -> 7287 | O21: ='01_Raw_Data_Mercedes'!F32 -> 21466 | P21: ='01_Raw_Data_Volkswagen'!F35 -> 43725 | Q21: ='01_Raw_Data_BMW'!G23 -> 5748 | R21: ='01_Raw_Data_Mercedes'!G32 -> 26444 | S21: ='01_Raw_Data_Volkswagen'!G35 -> 43823
A22: Receivables from Financial Services / Subsidiaries | B22: ='01_Raw_Data_BMW'!B25 -> 15650 | C22: ='01_Raw_Data_Mercedes'!B34 -> 34387 | D22: ='01_Raw_Data_Volkswagen'!B37 -> 70026 | E22: ='01_Raw_Data_BMW'!C25 -> 13546 | F22: ='01_Raw_Data_Mercedes'!C34 -> 39320 | G22: ='01_Raw_Data_Volkswagen'!C37 -> 68855 | H22: ='01_Raw_Data_BMW'!D25 -> 16398 | I22: ='01_Raw_Data_Mercedes'!D34 -> 38469 | J22: ='01_Raw_Data_Volkswagen'!D37 -> 66381 | K22: ='01_Raw_Data_BMW'!E25 -> 24510 | L22: ='01_Raw_Data_Mercedes'!E34 -> 37312 | M22: ='01_Raw_Data_Volkswagen'!E37 -> 61549 | N22: ='01_Raw_Data_BMW'!F25 -> 21019 | O22: ='01_Raw_Data_Mercedes'!F34 -> 33670 | P22: ='01_Raw_Data_Volkswagen'!F37 -> 56498 | Q22: ='01_Raw_Data_BMW'!G25 -> 18939 | R22: ='01_Raw_Data_Mercedes'!G34 -> 42476 | S22: ='01_Raw_Data_Volkswagen'!G37 -> 58006
A23: Other Current Assets | B23: ='01_Raw_Data_BMW'!B26+'01_Raw_Data_BMW'!B27 -> 6674 | C23: ='01_Raw_Data_Mercedes'!B84 -> 25707 | D23: ='01_Raw_Data_Volkswagen'!B85 -> 62235 | E23: ='01_Raw_Data_BMW'!C26+'01_Raw_Data_BMW'!C27 -> 5757 | F23: ='01_Raw_Data_Mercedes'!C84 -> 14729 | G23: ='01_Raw_Data_Volkswagen'!C85 -> 58230 | H23: ='01_Raw_Data_BMW'!D26+'01_Raw_Data_BMW'!D27 -> 5825 | I23: ='01_Raw_Data_Mercedes'!D84 -> 15026 | J23: ='01_Raw_Data_Volkswagen'!D85 -> 54363 | K23: ='01_Raw_Data_BMW'!E26+'01_Raw_Data_BMW'!E27 -> 5185 | L23: ='01_Raw_Data_Mercedes'!E84 -> 14162 | M23: ='01_Raw_Data_Volkswagen'!E85 -> 62632 | N23: ='01_Raw_Data_BMW'!F26+'01_Raw_Data_BMW'!F27 -> 7148 | O23: ='01_Raw_Data_Mercedes'!F84 -> 17000 | P23: ='01_Raw_Data_Volkswagen'!F85 -> 44881 | Q23: ='01_Raw_Data_BMW'!G26+'01_Raw_Data_BMW'!G27 -> 7185 | R23: ='01_Raw_Data_Mercedes'!G84 -> 12647 | S23: ='01_Raw_Data_Volkswagen'!G85 -> 42963
A24: Total Current Assets | B24: ='01_Raw_Data_BMW'!B29 -> 39191 | C24: ='01_Raw_Data_Mercedes'!B41 -> 102132 | D24: ='01_Raw_Data_Volkswagen'!B44 -> 247865 | E24: ='01_Raw_Data_BMW'!C29 -> 36216 | F24: ='01_Raw_Data_Mercedes'!C41 -> 101767 | G24: ='01_Raw_Data_Volkswagen'!C44 -> 245231 | H24: ='01_Raw_Data_BMW'!D29 -> 38222 | I24: ='01_Raw_Data_Mercedes'!D41 -> 104032 | J24: ='01_Raw_Data_Volkswagen'!D44 -> 239644 | K24: ='01_Raw_Data_BMW'!E29 -> 44586 | L24: ='01_Raw_Data_Mercedes'!E41 -> 102874 | M24: ='01_Raw_Data_Volkswagen'!E44 -> 224159 | N24: ='01_Raw_Data_BMW'!F29 -> 45036 | O24: ='01_Raw_Data_Mercedes'!F41 -> 102929 | P24: ='01_Raw_Data_Volkswagen'!F44 -> 200347 | Q24: ='01_Raw_Data_BMW'!G29 -> 39472 | R24: ='01_Raw_Data_Mercedes'!G41 -> 115264 | S24: ='01_Raw_Data_Volkswagen'!G44 -> 194944
A25: Intangible Assets | B25: ='01_Raw_Data_BMW'!B19 -> 1224 | C25: ='01_Raw_Data_Mercedes'!B21 -> 20547 | D25: ='01_Raw_Data_Volkswagen'!B23 -> 91474 | E25: ='01_Raw_Data_BMW'!C19 -> 1606 | F25: ='01_Raw_Data_Mercedes'!C21 -> 19436 | G25: ='01_Raw_Data_Volkswagen'!C23 -> 93333 | H25: ='01_Raw_Data_BMW'!D19 -> 1823 | I25: ='01_Raw_Data_Mercedes'!D21 -> 17593 | J25: ='01_Raw_Data_Volkswagen'!D23 -> 89109 | K25: ='01_Raw_Data_BMW'!E19 -> 1444 | L25: ='01_Raw_Data_Mercedes'!E21 -> 15869 | M25: ='01_Raw_Data_Volkswagen'!E23 -> 83241 | N25: ='01_Raw_Data_BMW'!F19 -> 704 | O25: ='01_Raw_Data_Mercedes'!F21 -> 15005 | P25: ='01_Raw_Data_Volkswagen'!F23 -> 77689 | Q25: ='01_Raw_Data_BMW'!G19 -> 488 | R25: ='01_Raw_Data_Mercedes'!G21 -> 16399 | S25: ='01_Raw_Data_Volkswagen'!G23 -> 67968
A26: Property, Plant & Equipment / Lease Assets | B26: ='01_Raw_Data_BMW'!B20 -> 17184 | C26: ='01_Raw_Data_Mercedes'!B80 -> 66812 | D26: ='01_Raw_Data_Volkswagen'!B81 -> 155562 | E26: ='01_Raw_Data_BMW'!C20 -> 16623 | F26: ='01_Raw_Data_Mercedes'!C80 -> 71757 | G26: ='01_Raw_Data_Volkswagen'!C81 -> 144645 | H26: ='01_Raw_Data_BMW'!D20 -> 15560 | I26: ='01_Raw_Data_Mercedes'!D80 -> 67802 | J26: ='01_Raw_Data_Volkswagen'!D81 -> 130974 | K26: ='01_Raw_Data_BMW'!E20 -> 14004 | L26: ='01_Raw_Data_Mercedes'!E80 -> 68802 | M26: ='01_Raw_Data_Volkswagen'!E81 -> 123270 | N26: ='01_Raw_Data_BMW'!F20 -> 12740 | O26: ='01_Raw_Data_Mercedes'!F80 -> 72330 | P26: ='01_Raw_Data_Volkswagen'!F81 -> 123394 | Q26: ='01_Raw_Data_BMW'!G20 -> 12520 | R26: ='01_Raw_Data_Mercedes'!G80 -> 82798 | S26: ='01_Raw_Data_Volkswagen'!G81 -> 114570
A27: Investments / Financial Receivables | B27: ='01_Raw_Data_BMW'!B21 -> 12001 | C27: ='01_Raw_Data_Mercedes'!B82 -> 52565 | D27: ='01_Raw_Data_Volkswagen'!B83 -> 119201 | E27: ='01_Raw_Data_BMW'!C21 -> 12020 | F27: ='01_Raw_Data_Mercedes'!C82 -> 61977 | G27: ='01_Raw_Data_Volkswagen'!C83 -> 117709 | H27: ='01_Raw_Data_BMW'!D21 -> 12077 | I27: ='01_Raw_Data_Mercedes'!D82 -> 63545 | J27: ='01_Raw_Data_Volkswagen'!D83 -> 111776 | K27: ='01_Raw_Data_BMW'!E21 -> 12093 | L27: ='01_Raw_Data_Mercedes'!E82 -> 62590 | M27: ='01_Raw_Data_Volkswagen'!E83 -> 103711 | N27: ='01_Raw_Data_BMW'!F21 -> 5067 | O27: ='01_Raw_Data_Mercedes'!F82 -> 61416 | P27: ='01_Raw_Data_Volkswagen'!F83 -> 101100 | Q27: ='01_Raw_Data_BMW'!G21 -> 3826 | R27: ='01_Raw_Data_Mercedes'!G82 -> 59939 | S27: ='01_Raw_Data_Volkswagen'!G83 -> 95068
A28: Other Non-Current Assets | B28: ='01_Raw_Data_BMW'!B30+'01_Raw_Data_BMW'!B31 -> 128 | C28: ='01_Raw_Data_Mercedes'!B83 -> 13410 | D28: ='01_Raw_Data_Volkswagen'!B84 -> 30365 | E28: ='01_Raw_Data_BMW'!C30+'01_Raw_Data_BMW'!C31 -> 105 | F28: ='01_Raw_Data_Mercedes'!C83 -> 10073 | G28: ='01_Raw_Data_Volkswagen'!C84 -> 31987 | H28: ='01_Raw_Data_BMW'!D30+'01_Raw_Data_BMW'!D31 -> 142 | I28: ='01_Raw_Data_Mercedes'!D83 -> 10050 | J28: ='01_Raw_Data_Volkswagen'!D84 -> 28836 | K28: ='01_Raw_Data_BMW'!E30+'01_Raw_Data_BMW'!E31 -> 116 | L28: ='01_Raw_Data_Mercedes'!E83 -> 9880 | M28: ='01_Raw_Data_Volkswagen'!E84 -> 29632 | N28: ='01_Raw_Data_BMW'!F30+'01_Raw_Data_BMW'!F31 -> 1158 | O28: ='01_Raw_Data_Mercedes'!F83 -> 8151 | P28: ='01_Raw_Data_Volkswagen'!F84 -> 26079 | Q28: ='01_Raw_Data_BMW'!G30+'01_Raw_Data_BMW'!G31 -> 1334 | R28: ='01_Raw_Data_Mercedes'!G83 -> 11337 | S28: ='01_Raw_Data_Volkswagen'!G84 -> 24563
A29: Total Assets | B29: ='01_Raw_Data_BMW'!B32 -> 69728 | C29: ='01_Raw_Data_Mercedes'!B42 -> 255466 | D29: ='01_Raw_Data_Volkswagen'!B45 -> 644467 | E29: ='01_Raw_Data_BMW'!C32 -> 66570 | F29: ='01_Raw_Data_Mercedes'!C42 -> 265010 | G29: ='01_Raw_Data_Volkswagen'!C45 -> 632905 | H29: ='01_Raw_Data_BMW'!D32 -> 67824 | I29: ='01_Raw_Data_Mercedes'!D42 -> 263022 | J29: ='01_Raw_Data_Volkswagen'!D45 -> 600338 | K29: ='01_Raw_Data_BMW'!E32 -> 72243 | L29: ='01_Raw_Data_Mercedes'!E42 -> 260015 | M29: ='01_Raw_Data_Volkswagen'!E45 -> 564013 | N29: ='01_Raw_Data_BMW'!F32 -> 64705 | O29: ='01_Raw_Data_Mercedes'!F42 -> 259831 | P29: ='01_Raw_Data_Volkswagen'!F45 -> 528609 | Q29: ='01_Raw_Data_BMW'!G32 -> 57640 | R29: ='01_Raw_Data_Mercedes'!G42 -> 285737 | S29: ='01_Raw_Data_Volkswagen'!G45 -> 497114
A31: Equity & Liabilities
A32: Total Equity | B32: ='01_Raw_Data_BMW'!B38 -> 16752 | C32: ='01_Raw_Data_Mercedes'!B50 -> 94240 | D32: ='01_Raw_Data_Volkswagen'!B53 -> 203054 | E32: ='01_Raw_Data_BMW'!C38 -> 16675 | F32: ='01_Raw_Data_Mercedes'!C50 -> 93630 | G32: ='01_Raw_Data_Volkswagen'!C53 -> 196731 | H32: ='01_Raw_Data_BMW'!D38 -> 17932 | I32: ='01_Raw_Data_Mercedes'!D50 -> 92816 | J32: ='01_Raw_Data_Volkswagen'!D53 -> 189912 | K32: ='01_Raw_Data_BMW'!E38 -> 20218 | L32: ='01_Raw_Data_Mercedes'!E50 -> 86540 | M32: ='01_Raw_Data_Volkswagen'!E53 -> 178328 | N32: ='01_Raw_Data_BMW'!F38 -> 18927 | O32: ='01_Raw_Data_Mercedes'!F50 -> 73167 | P32: ='01_Raw_Data_Volkswagen'!F53 -> 146154 | Q32: ='01_Raw_Data_BMW'!G38 -> 15165 | R32: ='01_Raw_Data_Mercedes'!G50 -> 62248 | S32: ='01_Raw_Data_Volkswagen'!G53 -> 128783
A33: Provisions | B33: ='01_Raw_Data_BMW'!B41 -> 12050 | C33: ='01_Raw_Data_Mercedes'!B76 -> 16265 | D33: ='01_Raw_Data_Volkswagen'!B77 -> 79848 | E33: ='01_Raw_Data_BMW'!C41 -> 12508 | F33: ='01_Raw_Data_Mercedes'!C76 -> 15972 | G33: ='01_Raw_Data_Volkswagen'!C77 -> 84448 | H33: ='01_Raw_Data_BMW'!D41 -> 13768 | I33: ='01_Raw_Data_Mercedes'!D76 -> 16390 | J33: ='01_Raw_Data_Volkswagen'!D77 -> 81139 | K33: ='01_Raw_Data_BMW'!E41 -> 14557 | L33: ='01_Raw_Data_Mercedes'!E76 -> 17044 | M33: ='01_Raw_Data_Volkswagen'!E77 -> 80338 | N33: ='01_Raw_Data_BMW'!F41 -> 10417 | O33: ='01_Raw_Data_Mercedes'!F76 -> 21321 | P33: ='01_Raw_Data_Volkswagen'!F77 -> 96857 | Q33: ='01_Raw_Data_BMW'!G41 -> 10322 | R33: ='01_Raw_Data_Mercedes'!G76 -> 32520 | S33: ='01_Raw_Data_Volkswagen'!G77 -> 96238
A34: Financial Debt / Financing Liabilities | B34: ='01_Raw_Data_BMW'!B42+'01_Raw_Data_BMW'!B44 -> 28358 | C34: ='01_Raw_Data_Mercedes'!B77 -> 100006 | D34: ='01_Raw_Data_Volkswagen'!B78 -> 264703 | E34: ='01_Raw_Data_BMW'!C42+'01_Raw_Data_BMW'!C44 -> 23949 | F34: ='01_Raw_Data_Mercedes'!C77 -> 112798 | G34: ='01_Raw_Data_Volkswagen'!C78 -> 254081 | H34: ='01_Raw_Data_BMW'!D42+'01_Raw_Data_BMW'!D44 -> 22683 | I34: ='01_Raw_Data_Mercedes'!D77 -> 108638 | J34: ='01_Raw_Data_Volkswagen'!D78 -> 232799 | K34: ='01_Raw_Data_BMW'!E42+'01_Raw_Data_BMW'!E44 -> 25704 | L34: ='01_Raw_Data_Mercedes'!E77 -> 111837 | M34: ='01_Raw_Data_Volkswagen'!E78 -> 205185 | N34: ='01_Raw_Data_BMW'!F42+'01_Raw_Data_BMW'!F44 -> 24463 | O34: ='01_Raw_Data_Mercedes'!F77 -> 125843 | P34: ='01_Raw_Data_Volkswagen'!F78 -> 210202 | Q34: ='01_Raw_Data_BMW'!G42+'01_Raw_Data_BMW'!G44 -> 23505 | R34: ='01_Raw_Data_Mercedes'!G77 -> 145842 | S34: ='01_Raw_Data_Volkswagen'!G78 -> 203457
A35: Trade Payables | B35: ='01_Raw_Data_BMW'!B43 -> 7097 | C35: ='01_Raw_Data_Mercedes'!B61 -> 10665 | D35: ='01_Raw_Data_Volkswagen'!B63 -> 30490 | E35: ='01_Raw_Data_BMW'!C43 -> 6892 | F35: ='01_Raw_Data_Mercedes'!C61 -> 11312 | G35: ='01_Raw_Data_Volkswagen'!C63 -> 29772 | H35: ='01_Raw_Data_BMW'!D43 -> 7552 | I35: ='01_Raw_Data_Mercedes'!D61 -> 12828 | J35: ='01_Raw_Data_Volkswagen'!D63 -> 30901 | K35: ='01_Raw_Data_BMW'!E43 -> 6786 | L35: ='01_Raw_Data_Mercedes'!E61 -> 12204 | M35: ='01_Raw_Data_Volkswagen'!E63 -> 28738 | N35: ='01_Raw_Data_BMW'!F43 -> 6531 | O35: ='01_Raw_Data_Mercedes'!F61 -> 10655 | P35: ='01_Raw_Data_Volkswagen'!F63 -> 23624 | Q35: ='01_Raw_Data_BMW'!G43 -> 4785 | R35: ='01_Raw_Data_Mercedes'!G61 -> 12378 | S35: ='01_Raw_Data_Volkswagen'!G63 -> 22677
A36: Other Liabilities | B36: ='01_Raw_Data_BMW'!B45+'01_Raw_Data_BMW'!B47 -> 5449 | C36: ='01_Raw_Data_Mercedes'!B78 -> 34290 | D36: ='01_Raw_Data_Volkswagen'!B79 -> 66372 | E36: ='01_Raw_Data_BMW'!C45+'01_Raw_Data_BMW'!C47 -> 6523 | F36: ='01_Raw_Data_Mercedes'!C78 -> 31298 | G36: ='01_Raw_Data_Volkswagen'!C79 -> 67872 | H36: ='01_Raw_Data_BMW'!D45+'01_Raw_Data_BMW'!D47 -> 5865 | I36: ='01_Raw_Data_Mercedes'!D78 -> 32350 | J36: ='01_Raw_Data_Volkswagen'!D79 -> 65588 | K36: ='01_Raw_Data_BMW'!E45+'01_Raw_Data_BMW'!E47 -> 4953 | L36: ='01_Raw_Data_Mercedes'!E78 -> 32390 | M36: ='01_Raw_Data_Volkswagen'!E79 -> 71424 | N36: ='01_Raw_Data_BMW'!F45+'01_Raw_Data_BMW'!F47 -> 4341 | O36: ='01_Raw_Data_Mercedes'!F78 -> 28845 | P36: ='01_Raw_Data_Volkswagen'!F79 -> 51771 | Q36: ='01_Raw_Data_BMW'!G45+'01_Raw_Data_BMW'!G47 -> 3836 | R36: ='01_Raw_Data_Mercedes'!G78 -> 32749 | S36: ='01_Raw_Data_Volkswagen'!G79 -> 45961
A37: Total Current Liabilities | B37: ='01_Raw_Data_BMW'!B46 -> 36043 | C37: ='01_Raw_Data_Mercedes'!B70 -> 73768 | D37: ='01_Raw_Data_Volkswagen'!B70 -> 226525 | E37: ='01_Raw_Data_BMW'!C46 -> 32635 | F37: ='01_Raw_Data_Mercedes'!C70 -> 74826 | G37: ='01_Raw_Data_Volkswagen'!C70 -> 217039 | H37: ='01_Raw_Data_BMW'!D46 -> 31599 | I37: ='01_Raw_Data_Mercedes'!D70 -> 82434 | J37: ='01_Raw_Data_Volkswagen'!D70 -> 205874 | K37: ='01_Raw_Data_BMW'!E46 -> 33392 | L37: ='01_Raw_Data_Mercedes'!E70 -> 88403 | M37: ='01_Raw_Data_Volkswagen'!E70 -> 182723 | N37: ='01_Raw_Data_BMW'!F46 -> 31456 | O37: ='01_Raw_Data_Mercedes'!F70 -> 87675 | P37: ='01_Raw_Data_Volkswagen'!F70 -> 164393 | Q37: ='01_Raw_Data_BMW'!G46 -> 28511 | R37: ='01_Raw_Data_Mercedes'!G70 -> 99809 | S37: ='01_Raw_Data_Volkswagen'!G70 -> 165410
A38: Total Liabilities | B38: =SUM(B33:B36) -> 52954 | C38: =SUM(C33:C36) -> 161226 | D38: =SUM(D33:D36) -> 441413 | E38: =SUM(E33:E36) -> 49872 | F38: =SUM(F33:F36) -> 171380 | G38: =SUM(G33:G36) -> 436173 | H38: =SUM(H33:H36) -> 49868 | I38: =SUM(I33:I36) -> 170206 | ... S38: =SUM(S33:S36) -> 368333
A39: Total Equity and Liabilities | B39: ='01_Raw_Data_BMW'!B48 -> 69728 | C39: ='01_Raw_Data_Mercedes'!B72 -> 255466 | D39: ='01_Raw_Data_Volkswagen'!B72 -> 644467 | E39: ='01_Raw_Data_BMW'!C48 -> 66570 | F39: ='01_Raw_Data_Mercedes'!C72 -> 265010 | G39: ='01_Raw_Data_Volkswagen'!C72 -> 632905 | H39: ='01_Raw_Data_BMW'!D48 -> 67824 | I39: ='01_Raw_Data_Mercedes'!D72 -> 263022 | J39: ='01_Raw_Data_Volkswagen'!D72 -> 600338 | K39: ='01_Raw_Data_BMW'!E48 -> 72243 | L39: ='01_Raw_Data_Mercedes'!E72 -> 260015 | M39: ='01_Raw_Data_Volkswagen'!E72 -> 564013 | N39: ='01_Raw_Data_BMW'!F48 -> 64705 | O39: ='01_Raw_Data_Mercedes'!F72 -> 259831 | P39: ='01_Raw_Data_Volkswagen'!F72 -> 528609 | Q39: ='01_Raw_Data_BMW'!G48 -> 57640 | R39: ='01_Raw_Data_Mercedes'!G72 -> 285737 | S39: ='01_Raw_Data_Volkswagen'!G72 -> 497114
A42: Average Assets | B42: ='01_Raw_Data_BMW'!B53 -> 68149 | C42: ='01_Raw_Data_Mercedes'!B85 -> 260238 | D42: ='01_Raw_Data_Volkswagen'!B86 -> 638686 | E42: ='01_Raw_Data_BMW'!C53 -> 67197 | F42: ='01_Raw_Data_Mercedes'!C85 -> 264016 | G42: ='01_Raw_Data_Volkswagen'!C86 -> 616621.5 | H42: ='01_Raw_Data_BMW'!D53 -> 70033.5 | I42: ='01_Raw_Data_Mercedes'!D85 -> 261518.5 | J42: ='01_Raw_Data_Volkswagen'!D86 -> 582175.5 | K42: ='01_Raw_Data_BMW'!E53 -> 68474 | L42: ='01_Raw_Data_Mercedes'!E85 -> 259923 | M42: ='01_Raw_Data_Volkswagen'!E86 -> 546311 | N42: ='01_Raw_Data_BMW'!F53 -> 61172.5 | O42: ='01_Raw_Data_Mercedes'!F85 -> 272784 | P42: ='01_Raw_Data_Volkswagen'!F86 -> 512861.5

Sheet 02_Common_Size_IS_BS
A2: Year | B2: 2025 | E2: 2024 | H2: 2023 | K2: 2022 | N2: 2021
A3: Item | B3: BMW | C3: Mercedes | D3: Volkswagen | E3: BMW | F3: Mercedes | G3: Volkswagen | H3: BMW | I3: Mercedes | J3: Volkswagen | K3: BMW | L3: Mercedes | M3: Volkswagen | N3: BMW | O3: Mercedes | P3: Volkswagen
A4: Revenues | B4: ='01_All_Raw_Data'!B4 -> 98805 | C4: ='01_All_Raw_Data'!C4 -> 132214 | D4: ='01_All_Raw_Data'!D4 -> 321913 | E4: ='01_All_Raw_Data'!E4 -> 105317 | F4: ='01_All_Raw_Data'!F4 -> 145594 | G4: ='01_All_Raw_Data'!G4 -> 324656 | H4: ='01_All_Raw_Data'!H4 -> 107874 | I4: ='01_All_Raw_Data'!I4 -> 153218 | ... P4: ='01_All_Raw_Data'!P4 -> 250200 | Q4: 1
A5: Revenue | B5: 1 | C5: 1 | D5: 1 | E5: 1 | F5: 1 | G5: 1 | H5: 1 | I5: 1 | J5: 1 | K5: 1 | L5: 1 | M5: 1 | N5: 1 | O5: 1 | P5: 1
A6: Cost of Sales | B6: ='01_All_Raw_Data'!B5/'02_Common_Size_IS_BS'!B$4 -> -0.84921816 | C6: ='01_All_Raw_Data'!C5/'02_Common_Size_IS_BS'!C$4 -> -0.83108445 | D6: ='01_All_Raw_Data'!D5/'02_Common_Size_IS_BS'!D$4 -> -0.84082035 | E6: ='01_All_Raw_Data'!E5/'02_Common_Size_IS_BS'!E$4 -> -0.83760457 | F6: ='01_All_Raw_Data'!F5/'02_Common_Size_IS_BS'!F$4 -> -0.80372818 | G6: ='01_All_Raw_Data'!G5/'02_Common_Size_IS_BS'!G$4 -> -0.81681534 | H6: ='01_All_Raw_Data'!H5/'02_Common_Size_IS_BS'!H$4 -> -0.84232531 | I6: ='01_All_Raw_Data'!I5/'02_Common_Size_IS_BS'!I$4 -> -0.77562036 | ... P6: ='01_All_Raw_Data'!P5/'02_Common_Size_IS_BS'!P$4 -> -0.81118705
A7: Gross Profit | B7: ='01_All_Raw_Data'!B6/'02_Common_Size_IS_BS'!B$4 -> 0.15078184 | C7: ='01_All_Raw_Data'!C6/'02_Common_Size_IS_BS'!C$4 -> 0.16891555 | D7: ='01_All_Raw_Data'!D6/'02_Common_Size_IS_BS'!D$4 -> 0.15918276 | E7: ='01_All_Raw_Data'!E6/'02_Common_Size_IS_BS'!E$4 -> 0.16239543 | F7: ='01_All_Raw_Data'!F6/'02_Common_Size_IS_BS'!F$4 -> 0.19627182 | G7: ='01_All_Raw_Data'!G6/'02_Common_Size_IS_BS'!G$4 -> 0.18318466 | H7: ='01_All_Raw_Data'!H6/'02_Common_Size_IS_BS'!H$4 -> 0.15767469 | I7: ='01_All_Raw_Data'!I6/'02_Common_Size_IS_BS'!I$4 -> 0.22437964 | ... P7: ='01_All_Raw_Data'!P6/'02_Common_Size_IS_BS'!P$4 -> 0.18881295
A8: Total Operating Expenses | B8: ='01_All_Raw_Data'!B7/'02_Common_Size_IS_BS'!B$4 -> -0.15354486 | C8: ='01_All_Raw_Data'!C7/'02_Common_Size_IS_BS'!C$4 -> -0.1340554 | D8: ='01_All_Raw_Data'!D7/'02_Common_Size_IS_BS'!D$4 -> -0.13163184 | E8: ='01_All_Raw_Data'!E7/'02_Common_Size_IS_BS'!E$4 -> -0.15700219 | F8: ='01_All_Raw_Data'!F7/'02_Common_Size_IS_BS'!F$4 -> -0.11043037 | G8: ='01_All_Raw_Data'!G7/'02_Common_Size_IS_BS'!G$4 -> -0.12447637 | H8: ='01_All_Raw_Data'!H7/'02_Common_Size_IS_BS'!H$4 -> -0.13966294 | I8: ='01_All_Raw_Data'!I7/'02_Common_Size_IS_BS'!I$4 -> -0.11066585 | ... P8: ='01_All_Raw_Data'!P7/'02_Common_Size_IS_BS'!P$4 -> -0.11177458
A9: Operating Profit (EBIT) | B9: ='01_All_Raw_Data'!B8/'02_Common_Size_IS_BS'!B$4 -> -0.0027630181 | C9: ='01_All_Raw_Data'!C8/'02_Common_Size_IS_BS'!C$4 -> 0.034860151 | D9: ='01_All_Raw_Data'!D8/'02_Common_Size_IS_BS'!D$4 -> 0.027550922 | E9: ='01_All_Raw_Data'!E8/'02_Common_Size_IS_BS'!E$4 -> 0.0053932414 | F9: ='01_All_Raw_Data'!F8/'02_Common_Size_IS_BS'!F$4 -> 0.08584145 | G9: ='01_All_Raw_Data'!G8/'02_Common_Size_IS_BS'!G$4 -> 0.058708294 | H9: ='01_All_Raw_Data'!H8/'02_Common_Size_IS_BS'!H$4 -> 0.018011754 | I9: ='01_All_Raw_Data'!I8/'02_Common_Size_IS_BS'!I$4 -> 0.11371379 | ... P9: ='01_All_Raw_Data'!P8/'02_Common_Size_IS_BS'!P$4 -> 0.077038369
A10: Other Income / Loss | B10: ='01_All_Raw_Data'!B9/'02_Common_Size_IS_BS'!B$4 -> 0.045564496 | C10: ='01_All_Raw_Data'!C9/'02_Common_Size_IS_BS'!C$4 -> 0.012668855 | D10: ='01_All_Raw_Data'!D9/'02_Common_Size_IS_BS'!D$4 -> 0.0013637225 | E10: ='01_All_Raw_Data'!E9/'02_Common_Size_IS_BS'!E$4 -> 0.033603312 | F10: ='01_All_Raw_Data'!F9/'02_Common_Size_IS_BS'!F$4 -> 0.011326016 | G10: ='01_All_Raw_Data'!G9/'02_Common_Size_IS_BS'!G$4 -> -0.0069427332 | H10: ='01_All_Raw_Data'!H9/'02_Common_Size_IS_BS'!H$4 -> 0.032519421 | I10: ='01_All_Raw_Data'!I9/'02_Common_Size_IS_BS'!I$4 -> 0.017367411 | ... P10: ='01_All_Raw_Data'!P9/'02_Common_Size_IS_BS'!P$4 -> 0.0033972822
A11: Profit Before Tax (EBT) | B11: ='01_All_Raw_Data'!B10/'02_Common_Size_IS_BS'!B$4 -> 0.042801478 | C11: ='01_All_Raw_Data'!C10/'02_Common_Size_IS_BS'!C$4 -> 0.047529006 | D11: ='01_All_Raw_Data'!D10/'02_Common_Size_IS_BS'!D$4 -> 0.028914645 | E11: ='01_All_Raw_Data'!E10/'02_Common_Size_IS_BS'!E$4 -> 0.038996553 | F11: ='01_All_Raw_Data'!F10/'02_Common_Size_IS_BS'!F$4 -> 0.097167466 | G11: ='01_All_Raw_Data'!G10/'02_Common_Size_IS_BS'!G$4 -> 0.051765561 | H11: ='01_All_Raw_Data'!H10/'02_Common_Size_IS_BS'!H$4 -> 0.050531175 | I11: ='01_All_Raw_Data'!I10/'02_Common_Size_IS_BS'!I$4 -> 0.1310812 | ... P11: ='01_All_Raw_Data'!P10/'02_Common_Size_IS_BS'!P$4 -> 0.080435651
A12: Income Taxes | B12: ='01_All_Raw_Data'!B11/'02_Common_Size_IS_BS'!B$4 -> -0.0028844694 | C12: ='01_All_Raw_Data'!C11/'02_Common_Size_IS_BS'!C$4 -> -0.0072080113 | D12: ='01_All_Raw_Data'!D11/'02_Common_Size_IS_BS'!D$4 -> -0.0074647498 | E12: ='01_All_Raw_Data'!E11/'02_Common_Size_IS_BS'!E$4 -> -0.0053742511 | F12: ='01_All_Raw_Data'!F11/'02_Common_Size_IS_BS'!F$4 -> -0.025674135 | G12: ='01_All_Raw_Data'!G11/'02_Common_Size_IS_BS'!G$4 -> -0.013586689 | H12: ='01_All_Raw_Data'!H11/'02_Common_Size_IS_BS'!H$4 -> -0.0098911693 | I12: ='01_All_Raw_Data'!I11/'02_Common_Size_IS_BS'!I$4 -> -0.036242478 | ... P12: ='01_All_Raw_Data'!P11/'02_Common_Size_IS_BS'!P$4 -> -0.018776978
A13: Other taxes | B13: ='01_All_Raw_Data'!B12/'02_Common_Size_IS_BS'!B$4 -> -0.00017205607 | C13: ='01_All_Raw_Data'!C12/'02_Common_Size_IS_BS'!C$4 -> 0 | D13: ='01_All_Raw_Data'!D12/'02_Common_Size_IS_BS'!D$4 -> 0 | E13: ='01_All_Raw_Data'!E12/'02_Common_Size_IS_BS'!E$4 -> -0.00016141743 | F13: ='01_All_Raw_Data'!F12/'02_Common_Size_IS_BS'!F$4 -> 0 | G13: ='01_All_Raw_Data'!G12/'02_Common_Size_IS_BS'!G$4 -> 0 | H13: ='01_All_Raw_Data'!H12/'02_Common_Size_IS_BS'!H$4 -> -0.00016686134 | I13: ='01_All_Raw_Data'!I12/'02_Common_Size_IS_BS'!I$4 -> 0 | ... P13: ='01_All_Raw_Data'!P12/'02_Common_Size_IS_BS'!P$4 -> 0
A14: Discontinued Operations (After Tax) | B14: ='01_All_Raw_Data'!B13/'02_Common_Size_IS_BS'!B$4 -> 0 | C14: ='01_All_Raw_Data'!C13/'02_Common_Size_IS_BS'!C$4 -> 0 | D14: ='01_All_Raw_Data'!D13/'02_Common_Size_IS_BS'!D$4 -> 0 | E14: ='01_All_Raw_Data'!E13/'02_Common_Size_IS_BS'!E$4 -> 0 | F14: ='01_All_Raw_Data'!F13/'02_Common_Size_IS_BS'!F$4 -> 0 | G14: ='01_All_Raw_Data'!G13/'02_Common_Size_IS_BS'!G$4 -> 0 | H14: ='01_All_Raw_Data'!H13/'02_Common_Size_IS_BS'!H$4 -> 0 | I14: ='01_All_Raw_Data'!I13/'02_Common_Size_IS_BS'!I$4 -> 0 | ... P14: ='01_All_Raw_Data'!P13/'02_Common_Size_IS_BS'!P$4 -> 0
A15: Net profit | B15: ='01_All_Raw_Data'!B14/'02_Common_Size_IS_BS'!B$4 -> 0.039744952 | C15: ='01_All_Raw_Data'!C14/'02_Common_Size_IS_BS'!C$4 -> 0.040320995 | D15: ='01_All_Raw_Data'!D14/'02_Common_Size_IS_BS'!D$4 -> 0.021449895 | E15: ='01_All_Raw_Data'!E14/'02_Common_Size_IS_BS'!E$4 -> 0.033460885 | F15: ='01_All_Raw_Data'!F14/'02_Common_Size_IS_BS'!F$4 -> 0.071493331 | G15: ='01_All_Raw_Data'!G14/'02_Common_Size_IS_BS'!G$4 -> 0.038178872 | H15: ='01_All_Raw_Data'!H14/'02_Common_Size_IS_BS'!H$4 -> 0.040473145 | I15: ='01_All_Raw_Data'!I14/'02_Common_Size_IS_BS'!I$4 -> 0.094838727 | ... P15: ='01_All_Raw_Data'!P14/'02_Common_Size_IS_BS'!P$4 -> 0.061658673
A19: Year | B19: 2025 | E19: 2024 | H19: 2023 | K19: 2022 | N19: 2021
A20: Assets | B20: BMW | C20: Mercedes | D20: Volkswagen | E20: BMW | F20: Mercedes | G20: Volkswagen | H20: BMW | I20: Mercedes | J20: Volkswagen | K20: BMW | L20: Mercedes | M20: Volkswagen | N20: BMW | O20: Mercedes | P20: Volkswagen
A21: Cash & Cash Equivalents | B21: ='01_All_Raw_Data'!B19/'02_Common_Size_IS_BS'!B$31 -> 0.12056849 | C21: ='01_All_Raw_Data'!C19/'02_Common_Size_IS_BS'!C$31 -> 0.047967244 | D21: ='01_All_Raw_Data'!D19/'02_Common_Size_IS_BS'!D$31 -> 0.060206341 | E21: ='01_All_Raw_Data'!E19/'02_Common_Size_IS_BS'!E$31 -> 0.12230735 | F21: ='01_All_Raw_Data'!F19/'02_Common_Size_IS_BS'!F$31 -> 0.054756424 | G21: ='01_All_Raw_Data'!G19/'02_Common_Size_IS_BS'!G$31 -> 0.063668323 | H21: ='01_All_Raw_Data'!H19/'02_Common_Size_IS_BS'!H$31 -> 0.090602147 | I21: ='01_All_Raw_Data'!I19/'02_Common_Size_IS_BS'!I$31 -> 0.060686939 | ... P21: ='01_All_Raw_Data'!P19/'02_Common_Size_IS_BS'!P$31 -> 0.07514628
A22: Trade Receivables | B22: ='01_All_Raw_Data'!B20/'02_Common_Size_IS_BS'!B$31 -> 0.016693437 | C22: ='01_All_Raw_Data'!C20/'02_Common_Size_IS_BS'!C$31 -> 0.022903243 | D22: ='01_All_Raw_Data'!D20/'02_Common_Size_IS_BS'!D$31 -> 0.032212666 | E22: ='01_All_Raw_Data'!E20/'02_Common_Size_IS_BS'!E$31 -> 0.01509689 | F22: ='01_All_Raw_Data'!F20/'02_Common_Size_IS_BS'!F$31 -> 0.026312215 | G22: ='01_All_Raw_Data'!G20/'02_Common_Size_IS_BS'!G$31 -> 0.033385737 | H22: ='01_All_Raw_Data'!H20/'02_Common_Size_IS_BS'!H$31 -> 0.019889715 | I22: ='01_All_Raw_Data'!I20/'02_Common_Size_IS_BS'!I$31 -> 0.027682095 | ... P22: ='01_All_Raw_Data'!P20/'02_Common_Size_IS_BS'!P$31 -> 0.029361967
A23: Inventories | B23: ='01_All_Raw_Data'!B21/'02_Common_Size_IS_BS'!B$31 -> 0.10463515 | C23: ='01_All_Raw_Data'!C21/'02_Common_Size_IS_BS'!C$31 -> 0.0936837 | D23: ='01_All_Raw_Data'!D21/'02_Common_Size_IS_BS'!D$31 -> 0.086958681 | E23: ='01_All_Raw_Data'!E21/'02_Common_Size_IS_BS'!E$31 -> 0.11665916 | F23: ='01_All_Raw_Data'!F21/'02_Common_Size_IS_BS'!F$31 -> 0.098992491 | G23: ='01_All_Raw_Data'!G21/'02_Common_Size_IS_BS'!G$31 -> 0.089618505 | H23: ='01_All_Raw_Data'!H21/'02_Common_Size_IS_BS'!H$31 -> 0.12539809 | I23: ='01_All_Raw_Data'!I21/'02_Common_Size_IS_BS'!I$31 -> 0.10377079 | ... P23: ='01_All_Raw_Data'!P21/'02_Common_Size_IS_BS'!P$31 -> 0.082717093
A24: Receivables from Financial Services / Subsidiaries | B24: ='01_All_Raw_Data'!B22/'02_Common_Size_IS_BS'!B$31 -> 0.22444355 | C24: ='01_All_Raw_Data'!C22/'02_Common_Size_IS_BS'!C$31 -> 0.134605 | D24: ='01_All_Raw_Data'!D22/'02_Common_Size_IS_BS'!D$31 -> 0.10865723 | E24: ='01_All_Raw_Data'!E22/'02_Common_Size_IS_BS'!E$31 -> 0.20348505 | F24: ='01_All_Raw_Data'!F22/'02_Common_Size_IS_BS'!F$31 -> 0.14837176 | G24: ='01_All_Raw_Data'!G22/'02_Common_Size_IS_BS'!G$31 -> 0.108792 | H24: ='01_All_Raw_Data'!H22/'02_Common_Size_IS_BS'!H$31 -> 0.24177282 | I24: ='01_All_Raw_Data'!I22/'02_Common_Size_IS_BS'!I$31 -> 0.14625773 | ... P24: ='01_All_Raw_Data'!P22/'02_Common_Size_IS_BS'!P$31 -> 0.10688051
A25: Other Current Assets | B25: ='01_All_Raw_Data'!B23/'02_Common_Size_IS_BS'!B$31 -> 0.095714777 | C25: ='01_All_Raw_Data'!C23/'02_Common_Size_IS_BS'!C$31 -> 0.10062787 | D25: ='01_All_Raw_Data'!D23/'02_Common_Size_IS_BS'!D$31 -> 0.096568172 | E25: ='01_All_Raw_Data'!E23/'02_Common_Size_IS_BS'!E$31 -> 0.086480397 | F25: ='01_All_Raw_Data'!F23/'02_Common_Size_IS_BS'!F$31 -> 0.055579035 | G25: ='01_All_Raw_Data'!G23/'02_Common_Size_IS_BS'!G$31 -> 0.092004329 | H25: ='01_All_Raw_Data'!H23/'02_Common_Size_IS_BS'!H$31 -> 0.085884053 | I25: ='01_All_Raw_Data'!I23/'02_Common_Size_IS_BS'!I$31 -> 0.057128301 | ... P25: ='01_All_Raw_Data'!P23/'02_Common_Size_IS_BS'!P$31 -> 0.084903965
A26: Total Current Assets | B26: ='01_All_Raw_Data'!B24/'02_Common_Size_IS_BS'!B$31 -> 0.56205542 | C26: ='01_All_Raw_Data'!C24/'02_Common_Size_IS_BS'!C$31 -> 0.39978706 | D26: ='01_All_Raw_Data'!D24/'02_Common_Size_IS_BS'!D$31 -> 0.38460464 | E26: ='01_All_Raw_Data'!E24/'02_Common_Size_IS_BS'!E$31 -> 0.54402884 | F26: ='01_All_Raw_Data'!F24/'02_Common_Size_IS_BS'!F$31 -> 0.38401192 | G26: ='01_All_Raw_Data'!G24/'02_Common_Size_IS_BS'!G$31 -> 0.38746889 | H26: ='01_All_Raw_Data'!H24/'02_Common_Size_IS_BS'!H$31 -> 0.56354683 | I26: ='01_All_Raw_Data'!I24/'02_Common_Size_IS_BS'!I$31 -> 0.39552585 | ... P26: ='01_All_Raw_Data'!P24/'02_Common_Size_IS_BS'!P$31 -> 0.37900792
A27: Intangible Assets | B27: ='01_All_Raw_Data'!B25/'02_Common_Size_IS_BS'!B$31 -> 0.017553924 | C27: ='01_All_Raw_Data'!C25/'02_Common_Size_IS_BS'!C$31 -> 0.08042949 | D27: ='01_All_Raw_Data'!D25/'02_Common_Size_IS_BS'!D$31 -> 0.14193745 | E27: ='01_All_Raw_Data'!E25/'02_Common_Size_IS_BS'!E$31 -> 0.024124981 | F27: ='01_All_Raw_Data'!F25/'02_Common_Size_IS_BS'!F$31 -> 0.073340629 | G27: ='01_All_Raw_Data'!G25/'02_Common_Size_IS_BS'!G$31 -> 0.14746763 | H27: ='01_All_Raw_Data'!H25/'02_Common_Size_IS_BS'!H$31 -> 0.026878391 | I27: ='01_All_Raw_Data'!I25/'02_Common_Size_IS_BS'!I$31 -> 0.066887941 | ... P27: ='01_All_Raw_Data'!P25/'02_Common_Size_IS_BS'!P$31 -> 0.14696874
A28: Property, Plant & Equipment / Lease Assets | B28: ='01_All_Raw_Data'!B26/'02_Common_Size_IS_BS'!B$31 -> 0.24644332 | C28: ='01_All_Raw_Data'!C26/'02_Common_Size_IS_BS'!C$31 -> 0.26152991 | D28: ='01_All_Raw_Data'!D26/'02_Common_Size_IS_BS'!D$31 -> 0.24138086 | E28: ='01_All_Raw_Data'!E26/'02_Common_Size_IS_BS'!E$31 -> 0.24970708 | F28: ='01_All_Raw_Data'!F26/'02_Common_Size_IS_BS'!F$31 -> 0.27077091 | G28: ='01_All_Raw_Data'!G26/'02_Common_Size_IS_BS'!G$31 -> 0.22854141 | H28: ='01_All_Raw_Data'!H26/'02_Common_Size_IS_BS'!H$31 -> 0.22941732 | I28: ='01_All_Raw_Data'!I26/'02_Common_Size_IS_BS'!I$31 -> 0.25778072 | ... P28: ='01_All_Raw_Data'!P26/'02_Common_Size_IS_BS'!P$31 -> 0.23343152
A29: Investments / Financial Receivables | B29: ='01_All_Raw_Data'!B27/'02_Common_Size_IS_BS'!B$31 -> 0.17211163 | C29: ='01_All_Raw_Data'!C27/'02_Common_Size_IS_BS'!C$31 -> 0.20576124 | D29: ='01_All_Raw_Data'!D27/'02_Common_Size_IS_BS'!D$31 -> 0.1849606 | E29: ='01_All_Raw_Data'!E27/'02_Common_Size_IS_BS'!E$31 -> 0.18056181 | F29: ='01_All_Raw_Data'!F27/'02_Common_Size_IS_BS'!F$31 -> 0.23386665 | G29: ='01_All_Raw_Data'!G27/'02_Common_Size_IS_BS'!G$31 -> 0.1859821 | H29: ='01_All_Raw_Data'!H27/'02_Common_Size_IS_BS'!H$31 -> 0.17806381 | I29: ='01_All_Raw_Data'!I27/'02_Common_Size_IS_BS'!I$31 -> 0.24159576 | ... P29: ='01_All_Raw_Data'!P27/'02_Common_Size_IS_BS'!P$31 -> 0.19125668
A30: Other Non-Current Assets | B30: ='01_All_Raw_Data'!B28/'02_Common_Size_IS_BS'!B$31 -> 0.0018357045 | C30: ='01_All_Raw_Data'!C28/'02_Common_Size_IS_BS'!C$31 -> 0.052492308 | D30: ='01_All_Raw_Data'!D28/'02_Common_Size_IS_BS'!D$31 -> 0.047116454 | E30: ='01_All_Raw_Data'!E28/'02_Common_Size_IS_BS'!E$31 -> 0.0015772871 | F30: ='01_All_Raw_Data'!F28/'02_Common_Size_IS_BS'!F$31 -> 0.038009886 | G30: ='01_All_Raw_Data'!G28/'02_Common_Size_IS_BS'!G$31 -> 0.05053997 | H30: ='01_All_Raw_Data'!H28/'02_Common_Size_IS_BS'!H$31 -> 0.0020936542 | I30: ='01_All_Raw_Data'!I28/'02_Common_Size_IS_BS'!I$31 -> 0.038209732 | ... P30: ='01_All_Raw_Data'!P28/'02_Common_Size_IS_BS'!P$31 -> 0.049335142
A31: Total Assets | B31: ='01_All_Raw_Data'!B29 -> 69728 | C31: ='01_All_Raw_Data'!C29 -> 255466 | D31: ='01_All_Raw_Data'!D29 -> 644467 | E31: ='01_All_Raw_Data'!E29 -> 66570 | F31: ='01_All_Raw_Data'!F29 -> 265010 | G31: ='01_All_Raw_Data'!G29 -> 632905 | H31: ='01_All_Raw_Data'!H29 -> 67824 | I31: ='01_All_Raw_Data'!I29 -> 263022 | ... P31: ='01_All_Raw_Data'!P29 -> 528609 | Q31: 1
A33: Equity & Liabilities
A34: Total Equity | B34: ='01_All_Raw_Data'!B32/'02_Common_Size_IS_BS'!B$31 -> 0.24024782 | C34: ='01_All_Raw_Data'!C32/'02_Common_Size_IS_BS'!C$31 -> 0.36889449 | D34: ='01_All_Raw_Data'!D32/'02_Common_Size_IS_BS'!D$31 -> 0.31507277 | E34: ='01_All_Raw_Data'!E32/'02_Common_Size_IS_BS'!E$31 -> 0.25048821 | F34: ='01_All_Raw_Data'!F32/'02_Common_Size_IS_BS'!F$31 -> 0.35330742 | G34: ='01_All_Raw_Data'!G32/'02_Common_Size_IS_BS'!G$31 -> 0.31083812 | H34: ='01_All_Raw_Data'!H32/'02_Common_Size_IS_BS'!H$31 -> 0.26439019 | I34: ='01_All_Raw_Data'!I32/'02_Common_Size_IS_BS'!I$31 -> 0.35288303 | ... P34: ='01_All_Raw_Data'!P32/'02_Common_Size_IS_BS'!P$31 -> 0.27648791
A35: Provisions | B35: ='01_All_Raw_Data'!B33/'02_Common_Size_IS_BS'!B$31 -> 0.17281436 | C35: ='01_All_Raw_Data'!C33/'02_Common_Size_IS_BS'!C$31 -> 0.063667964 | D35: ='01_All_Raw_Data'!D33/'02_Common_Size_IS_BS'!D$31 -> 0.12389773 | E35: ='01_All_Raw_Data'!E33/'02_Common_Size_IS_BS'!E$31 -> 0.18789244 | F35: ='01_All_Raw_Data'!F33/'02_Common_Size_IS_BS'!F$31 -> 0.060269424 | G35: ='01_All_Raw_Data'!G33/'02_Common_Size_IS_BS'!G$31 -> 0.13342919 | H35: ='01_All_Raw_Data'!H33/'02_Common_Size_IS_BS'!H$31 -> 0.20299599 | I35: ='01_All_Raw_Data'!I33/'02_Common_Size_IS_BS'!I$31 -> 0.062314179 | ... P35: ='01_All_Raw_Data'!P33/'02_Common_Size_IS_BS'!P$31 -> 0.18322995
A36: Financial Debt / Financing Liabilities | B36: ='01_All_Raw_Data'!B34/'02_Common_Size_IS_BS'!B$31 -> 0.40669458 | C36: ='01_All_Raw_Data'!C34/'02_Common_Size_IS_BS'!C$31 -> 0.39146501 | D36: ='01_All_Raw_Data'!D34/'02_Common_Size_IS_BS'!D$31 -> 0.41073166 | E36: ='01_All_Raw_Data'!E34/'02_Common_Size_IS_BS'!E$31 -> 0.35975665 | F36: ='01_All_Raw_Data'!F34/'02_Common_Size_IS_BS'!F$31 -> 0.42563677 | G36: ='01_All_Raw_Data'!G34/'02_Common_Size_IS_BS'!G$31 -> 0.40145203 | H36: ='01_All_Raw_Data'!H34/'02_Common_Size_IS_BS'!H$31 -> 0.33443914 | I36: ='01_All_Raw_Data'!I34/'02_Common_Size_IS_BS'!I$31 -> 0.41303769 | ... P36: ='01_All_Raw_Data'!P34/'02_Common_Size_IS_BS'!P$31 -> 0.39765119
A37: Trade Payables | B37: ='01_All_Raw_Data'!B35/'02_Common_Size_IS_BS'!B$31 -> 0.10178121 | C37: ='01_All_Raw_Data'!C35/'02_Common_Size_IS_BS'!C$31 -> 0.041747238 | D37: ='01_All_Raw_Data'!D35/'02_Common_Size_IS_BS'!D$31 -> 0.047310413 | E37: ='01_All_Raw_Data'!E35/'02_Common_Size_IS_BS'!E$31 -> 0.10353012 | F37: ='01_All_Raw_Data'!F35/'02_Common_Size_IS_BS'!F$31 -> 0.042685182 | G37: ='01_All_Raw_Data'!G35/'02_Common_Size_IS_BS'!G$31 -> 0.047040235 | H37: ='01_All_Raw_Data'!H35/'02_Common_Size_IS_BS'!H$31 -> 0.11134702 | I37: ='01_All_Raw_Data'!I35/'02_Common_Size_IS_BS'!I$31 -> 0.048771586 | ... P37: ='01_All_Raw_Data'!P35/'02_Common_Size_IS_BS'!P$31 -> 0.044690877
A38: Other Liabilities | B38: ='01_All_Raw_Data'!B36/'02_Common_Size_IS_BS'!B$31 -> 0.078146512 | C38: ='01_All_Raw_Data'!C36/'02_Common_Size_IS_BS'!C$31 -> 0.1342253 | D38: ='01_All_Raw_Data'!D36/'02_Common_Size_IS_BS'!D$31 -> 0.10298743 | E38: ='01_All_Raw_Data'!E36/'02_Common_Size_IS_BS'!E$31 -> 0.097987081 | F38: ='01_All_Raw_Data'!F36/'02_Common_Size_IS_BS'!F$31 -> 0.1181012 | G38: ='01_All_Raw_Data'!G36/'02_Common_Size_IS_BS'!G$31 -> 0.10723884 | H38: ='01_All_Raw_Data'!H36/'02_Common_Size_IS_BS'!H$31 -> 0.086473815 | I38: ='01_All_Raw_Data'!I36/'02_Common_Size_IS_BS'!I$31 -> 0.12299351 | ... P38: ='01_All_Raw_Data'!P36/'02_Common_Size_IS_BS'!P$31 -> 0.097938174
A39: Total Current Liabilities | B39: ='01_All_Raw_Data'!B37/'02_Common_Size_IS_BS'!B$31 -> 0.51690856 | C39: ='01_All_Raw_Data'!C37/'02_Common_Size_IS_BS'!C$31 -> 0.28875858 | D39: ='01_All_Raw_Data'!D37/'02_Common_Size_IS_BS'!D$31 -> 0.35149201 | E39: ='01_All_Raw_Data'!E37/'02_Common_Size_IS_BS'!E$31 -> 0.49023584 | F39: ='01_All_Raw_Data'!F37/'02_Common_Size_IS_BS'!F$31 -> 0.28235161 | G39: ='01_All_Raw_Data'!G37/'02_Common_Size_IS_BS'!G$31 -> 0.34292508 | H39: ='01_All_Raw_Data'!H37/'02_Common_Size_IS_BS'!H$31 -> 0.46589703 | I39: ='01_All_Raw_Data'!I37/'02_Common_Size_IS_BS'!I$31 -> 0.31341105 | ... P39: ='01_All_Raw_Data'!P37/'02_Common_Size_IS_BS'!P$31 -> 0.31099168
A40: Total Liabilities | B40: ='01_All_Raw_Data'!B38/'02_Common_Size_IS_BS'!B$31 -> 0.75943667 | C40: ='01_All_Raw_Data'!C38/'02_Common_Size_IS_BS'!C$31 -> 0.63110551 | D40: ='01_All_Raw_Data'!D38/'02_Common_Size_IS_BS'!D$31 -> 0.68492723 | E40: ='01_All_Raw_Data'!E38/'02_Common_Size_IS_BS'!E$31 -> 0.74916629 | F40: ='01_All_Raw_Data'!F38/'02_Common_Size_IS_BS'!F$31 -> 0.64669258 | G40: ='01_All_Raw_Data'!G38/'02_Common_Size_IS_BS'!G$31 -> 0.6891603 | H40: ='01_All_Raw_Data'!H38/'02_Common_Size_IS_BS'!H$31 -> 0.73525596 | I40: ='01_All_Raw_Data'!I38/'02_Common_Size_IS_BS'!I$31 -> 0.64711697 | ... P40: ='01_All_Raw_Data'!P38/'02_Common_Size_IS_BS'!P$31 -> 0.72351019
A41: Total Equity and Liabilities | B41: ='01_All_Raw_Data'!B39/'02_Common_Size_IS_BS'!B$31 -> 1 | C41: ='01_All_Raw_Data'!C39/'02_Common_Size_IS_BS'!C$31 -> 1 | D41: ='01_All_Raw_Data'!D39/'02_Common_Size_IS_BS'!D$31 -> 1 | E41: ='01_All_Raw_Data'!E39/'02_Common_Size_IS_BS'!E$31 -> 1 | F41: ='01_All_Raw_Data'!F39/'02_Common_Size_IS_BS'!F$31 -> 1 | G41: ='01_All_Raw_Data'!G39/'02_Common_Size_IS_BS'!G$31 -> 1 | H41: ='01_All_Raw_Data'!H39/'02_Common_Size_IS_BS'!H$31 -> 1 | I41: ='01_All_Raw_Data'!I39/'02_Common_Size_IS_BS'!I$31 -> 1 | ... P41: ='01_All_Raw_Data'!P39/'02_Common_Size_IS_BS'!P$31 -> 1

Sheet 02_Common_Size_Output
A2: Gross Profit % | B2: 2021 | C2: 2022 | D2: 2023 | E2: 2024 | F2: 2025
A3: BMW | B3: {=INDEX('02_Common_Size_IS_BS'!$B$4:$P$15, MATCH("Gross Profit",'02_Common_Size_IS_BS'!$A$4:$A$15,0), MATCH(B$2,'02_Common_Size_IS_BS'!$B$2:$P$2,0)+MATCH($A3,'02_Common_Size_IS_BS'!$B$3:$D$3,0)-1)} -> 0.18348282 | C3: {=INDEX('02_Common_Size_IS_BS'!$B$4:$P$15, MATCH("Gross Profit",'02_Common_Size_IS_BS'!$A$4:$A$15,0), MATCH(C$2,'02_Common_Size_IS_BS'!$B$2:$P$2,0)+MATCH($A3,'02_Common_Size_IS_BS'!$B$3:$D$3,0)-1)} -> 0.17361118 | D3: {=INDEX('02_Common_Size_IS_BS'!$B$4:$P$15, MATCH("Gross Profit",'02_Common_Size_IS_BS'!$A$4:$A$15,0), MATCH(D$2,'02_Common_Size_IS_BS'!$B$2:$P$2,0)+MATCH($A3,'02_Common_Size_IS_BS'!$B$3:$D$3,0)-1)} -> 0.15767469 | E3: {=INDEX('02_Common_Size_IS_BS'!$B$4:$P$15, MATCH("Gross Profit",'02_Common_Size_IS_BS'!$A$4:$A$15,0), MATCH(E$2,'02_Common_Size_IS_BS'!$B$2:$P$2,0)+MATCH($A3,'02_Common_Size_IS_BS'!$B$3:$D$3,0)-1)} -> 0.16239543 | F3: {=INDEX('02_Common_Size_IS_BS'!$B$4:$P$15, MATCH("Gross Profit",'02_Common_Size_IS_BS'!$A$4:$A$15,0), MATCH(F$2,'02_Common_Size_IS_BS'!$B$2:$P$2,0)+MATCH($A3,'02_Common_Size_IS_BS'!$B$3:$D$3,0)-1)} -> 0.15078184
A4: Mercedes | B4: {=INDEX('02_Common_Size_IS_BS'!$B$4:$P$15, MATCH("Gross Profit",'02_Common_Size_IS_BS'!$A$4:$A$15,0), MATCH(B$2,'02_Common_Size_IS_BS'!$B$2:$P$2,0)+MATCH($A4,'02_Common_Size_IS_BS'!$B$3:$D$3,0)-1)} -> 0.22910085 | C4: {=INDEX('02_Common_Size_IS_BS'!$B$4:$P$15, MATCH("Gross Profit",'02_Common_Size_IS_BS'!$A$4:$A$15,0), MATCH(C$2,'02_Common_Size_IS_BS'!$B$2:$P$2,0)+MATCH($A4,'02_Common_Size_IS_BS'!$B$3:$D$3,0)-1)} -> 0.2267743 | D4: {=INDEX('02_Common_Size_IS_BS'!$B$4:$P$15, MATCH("Gross Profit",'02_Common_Size_IS_BS'!$A$4:$A$15,0), MATCH(D$2,'02_Common_Size_IS_BS'!$B$2:$P$2,0)+MATCH($A4,'02_Common_Size_IS_BS'!$B$3:$D$3,0)-1)} -> 0.22437964 | E4: {=INDEX('02_Common_Size_IS_BS'!$B$4:$P$15, MATCH("Gross Profit",'02_Common_Size_IS_BS'!$A$4:$A$15,0), MATCH(E$2,'02_Common_Size_IS_BS'!$B$2:$P$2,0)+MATCH($A4,'02_Common_Size_IS_BS'!$B$3:$D$3,0)-1)} -> 0.19627182 | F4: {=INDEX('02_Common_Size_IS_BS'!$B$4:$P$15, MATCH("Gross Profit",'02_Common_Size_IS_BS'!$A$4:$A$15,0), MATCH(F$2,'02_Common_Size_IS_BS'!$B$2:$P$2,0)+MATCH($A4,'02_Common_Size_IS_BS'!$B$3:$D$3,0)-1)} -> 0.16891555
A5: Volkswagen | B5: {=INDEX('02_Common_Size_IS_BS'!$B$4:$P$15, MATCH("Gross Profit",'02_Common_Size_IS_BS'!$A$4:$A$15,0), MATCH(B$2,'02_Common_Size_IS_BS'!$B$2:$P$2,0)+MATCH($A5,'02_Common_Size_IS_BS'!$B$3:$D$3,0)-1)} -> 0.18881295 | C5: {=INDEX('02_Common_Size_IS_BS'!$B$4:$P$15, MATCH("Gross Profit",'02_Common_Size_IS_BS'!$A$4:$A$15,0), MATCH(C$2,'02_Common_Size_IS_BS'!$B$2:$P$2,0)+MATCH($A5,'02_Common_Size_IS_BS'!$B$3:$D$3,0)-1)} -> 0.18700591 | D5: {=INDEX('02_Common_Size_IS_BS'!$B$4:$P$15, MATCH("Gross Profit",'02_Common_Size_IS_BS'!$A$4:$A$15,0), MATCH(D$2,'02_Common_Size_IS_BS'!$B$2:$P$2,0)+MATCH($A5,'02_Common_Size_IS_BS'!$B$3:$D$3,0)-1)} -> 0.18934232 | E5: {=INDEX('02_Common_Size_IS_BS'!$B$4:$P$15, MATCH("Gross Profit",'02_Common_Size_IS_BS'!$A$4:$A$15,0), MATCH(E$2,'02_Common_Size_IS_BS'!$B$2:$P$2,0)+MATCH($A5,'02_Common_Size_IS_BS'!$B$3:$D$3,0)-1)} -> 0.18318466 | F5: {=INDEX('02_Common_Size_IS_BS'!$B$4:$P$15, MATCH("Gross Profit",'02_Common_Size_IS_BS'!$A$4:$A$15,0), MATCH(F$2,'02_Common_Size_IS_BS'!$B$2:$P$2,0)+MATCH($A5,'02_Common_Size_IS_BS'!$B$3:$D$3,0)-1)} -> 0.15918276
A10: OPEX | B10: 2021 | C10: 2022 | D10: 2023 | E10: 2024 | F10: 2025
A11: BMW | B11: {=-INDEX('02_Common_Size_IS_BS'!$B$4:$P$15, MATCH("Total Operating Expenses",'02_Common_Size_IS_BS'!$A$4:$A$15,0), MATCH(B$10,'02_Common_Size_IS_BS'!$B$2:$P$2,0)+MATCH($A11,'02_Common_Size_IS_BS'!$B$3:$D$3,0)-1)} -> 0.14473714 | C11: {=-INDEX('02_Common_Size_IS_BS'!$B$4:$P$15, MATCH("Total Operating Expenses",'02_Common_Size_IS_BS'!$A$4:$A$15,0), MATCH(C$10,'02_Common_Size_IS_BS'!$B$2:$P$2,0)+MATCH($A11,'02_Common_Size_IS_BS'!$B$3:$D$3,0)-1)} -> 0.15002986 | D11: {=-INDEX('02_Common_Size_IS_BS'!$B$4:$P$15, MATCH("Total Operating Expenses",'02_Common_Size_IS_BS'!$A$4:$A$15,0), MATCH(D$10,'02_Common_Size_IS_BS'!$B$2:$P$2,0)+MATCH($A11,'02_Common_Size_IS_BS'!$B$3:$D$3,0)-1)} -> 0.13966294 | E11: {=-INDEX('02_Common_Size_IS_BS'!$B$4:$P$15, MATCH("Total Operating Expenses",'02_Common_Size_IS_BS'!$A$4:$A$15,0), MATCH(E$10,'02_Common_Size_IS_BS'!$B$2:$P$2,0)+MATCH($A11,'02_Common_Size_IS_BS'!$B$3:$D$3,0)-1)} -> 0.15700219 | F11: {=-INDEX('02_Common_Size_IS_BS'!$B$4:$P$15, MATCH("Total Operating Expenses",'02_Common_Size_IS_BS'!$A$4:$A$15,0), MATCH(F$10,'02_Common_Size_IS_BS'!$B$2:$P$2,0)+MATCH($A11,'02_Common_Size_IS_BS'!$B$3:$D$3,0)-1)} -> 0.15354486
A12: Mercedes | B12: {=-INDEX('02_Common_Size_IS_BS'!$B$4:$P$15, MATCH("Total Operating Expenses",'02_Common_Size_IS_BS'!$A$4:$A$15,0), MATCH(B$10,'02_Common_Size_IS_BS'!$B$2:$P$2,0)+MATCH($A12,'02_Common_Size_IS_BS'!$B$3:$D$3,0)-1)} -> 0.1218585 | C12: {=-INDEX('02_Common_Size_IS_BS'!$B$4:$P$15, MATCH("Total Operating Expenses",'02_Common_Size_IS_BS'!$A$4:$A$15,0), MATCH(C$10,'02_Common_Size_IS_BS'!$B$2:$P$2,0)+MATCH($A12,'02_Common_Size_IS_BS'!$B$3:$D$3,0)-1)} -> 0.10421486 | D12: {=-INDEX('02_Common_Size_IS_BS'!$B$4:$P$15, MATCH("Total Operating Expenses",'02_Common_Size_IS_BS'!$A$4:$A$15,0), MATCH(D$10,'02_Common_Size_IS_BS'!$B$2:$P$2,0)+MATCH($A12,'02_Common_Size_IS_BS'!$B$3:$D$3,0)-1)} -> 0.11066585 | E12: {=-INDEX('02_Common_Size_IS_BS'!$B$4:$P$15, MATCH("Total Operating Expenses",'02_Common_Size_IS_BS'!$A$4:$A$15,0), MATCH(E$10,'02_Common_Size_IS_BS'!$B$2:$P$2,0)+MATCH($A12,'02_Common_Size_IS_BS'!$B$3:$D$3,0)-1)} -> 0.11043037 | F12: {=-INDEX('02_Common_Size_IS_BS'!$B$4:$P$15, MATCH("Total Operating Expenses",'02_Common_Size_IS_BS'!$A$4:$A$15,0), MATCH(F$10,'02_Common_Size_IS_BS'!$B$2:$P$2,0)+MATCH($A12,'02_Common_Size_IS_BS'!$B$3:$D$3,0)-1)} -> 0.1340554
A13: Volkswagen | B13: {=-INDEX('02_Common_Size_IS_BS'!$B$4:$P$15, MATCH("Total Operating Expenses",'02_Common_Size_IS_BS'!$A$4:$A$15,0), MATCH(B$10,'02_Common_Size_IS_BS'!$B$2:$P$2,0)+MATCH($A13,'02_Common_Size_IS_BS'!$B$3:$D$3,0)-1)} -> 0.11177458 | C13: {=-INDEX('02_Common_Size_IS_BS'!$B$4:$P$15, MATCH("Total Operating Expenses",'02_Common_Size_IS_BS'!$A$4:$A$15,0), MATCH(C$10,'02_Common_Size_IS_BS'!$B$2:$P$2,0)+MATCH($A13,'02_Common_Size_IS_BS'!$B$3:$D$3,0)-1)} -> 0.1077728 | D13: {=-INDEX('02_Common_Size_IS_BS'!$B$4:$P$15, MATCH("Total Operating Expenses",'02_Common_Size_IS_BS'!$A$4:$A$15,0), MATCH(D$10,'02_Common_Size_IS_BS'!$B$2:$P$2,0)+MATCH($A13,'02_Common_Size_IS_BS'!$B$3:$D$3,0)-1)} -> 0.1192923 | E13: {=-INDEX('02_Common_Size_IS_BS'!$B$4:$P$15, MATCH("Total Operating Expenses",'02_Common_Size_IS_BS'!$A$4:$A$15,0), MATCH(E$10,'02_Common_Size_IS_BS'!$B$2:$P$2,0)+MATCH($A13,'02_Common_Size_IS_BS'!$B$3:$D$3,0)-1)} -> 0.12447637 | F13: {=-INDEX('02_Common_Size_IS_BS'!$B$4:$P$15, MATCH("Total Operating Expenses",'02_Common_Size_IS_BS'!$A$4:$A$15,0), MATCH(F$10,'02_Common_Size_IS_BS'!$B$2:$P$2,0)+MATCH($A13,'02_Common_Size_IS_BS'!$B$3:$D$3,0)-1)} -> 0.13163184
A18: EBIT | B18: 2021 | C18: 2022 | D18: 2023 | E18: 2024 | F18: 2025
